<?xml version="1.0" ?>
<!-- =================================================================================== -->
<!-- |    This document was autogenerated by xacro from urdf/irb2400_navigation_environment.xacro | -->
<!-- |    EDITING THIS FILE BY HAND IS NOT RECOMMENDED                                 | -->
<!-- =================================================================================== -->
<robot name="irb2400_navigation_environment" xmlns:xacro="http://ros.org/wiki/xacro">
  <description>
		Creates a window of specified dimensions using boxes
	</description>
  <description>
		Contains a series of material blocks with predefined colors that can be used
		in any visual element of a urdf model.
	</description>
  <description>
		Contains a series of material blocks with predefined colors that can be used
		in any visual element of a urdf model.
	</description>
  <!-- parameters -->
  <!-- instantiating windows -->
  <link name="window1_parent_frame"/>
  <link name="window1_top_link">
    <visual>
      <origin rpy="0 0 0" xyz="0 0.37 0"/>
      <geometry>
        <box size="0.8 0.1 1.0"/>
      </geometry>
      <material name="_blue_material">
        <color rgba="0 0 1 1"/>
      </material>
      <!--xacro:material_blue_block prefix="${name}"/-->
    </visual>
    <collision>
      <origin rpy="0 0 0" xyz="0 0.37 0"/>
      <geometry>
        <box size="0.8 0.1 1.0"/>
      </geometry>
      <material name="_red_material">
        <color rgba="1 0 0 1"/>
      </material>
      <!--xacro:material_red_block prefix="${name}"/-->
    </collision>
  </link>
  <joint name="window1_parent_frame_to_window1_top_link" type="fixed">
    <origin rpy="0 0 0" xyz="0 0 0"/>
    <parent link="window1_parent_frame"/>
    <child link="window1_top_link"/>
  </joint>
  <link name="window1_bottom_link">
    <visual>
      <origin rpy="0 0 0" xyz="0 -0.37 0"/>
      <geometry>
        <box size="0.8 0.1 1.0"/>
      </geometry>
      <material name="_blue_material">
        <color rgba="0 0 1 1"/>
      </material>
      <!--xacro:material_blue_block prefix="${name}"/-->
    </visual>
    <collision>
      <origin rpy="0 0 0" xyz="0 -0.37 0"/>
      <geometry>
        <box size="0.8 0.1 1.0"/>
      </geometry>
      <material name="_red_material">
        <color rgba="1 0 0 1"/>
      </material>
      <!--xacro:material_red_block prefix="${name}"/-->
    </collision>
  </link>
  <joint name="window1_parent_frame_to_window1_bottom_link" type="fixed">
    <origin rpy="0 0 0" xyz="0 0 0"/>
    <parent link="window1_parent_frame"/>
    <child link="window1_bottom_link"/>
  </joint>
  <link name="window1_left_link">
    <visual>
      <origin rpy="0 0 0" xyz="-0.35 0 0"/>
      <geometry>
        <box size="0.1 0.64 1.0"/>
      </geometry>
      <material name="_blue_material">
        <color rgba="0 0 1 1"/>
      </material>
      <!--xacro:material_blue_block prefix="${name}"/-->
    </visual>
    <collision>
      <origin rpy="0 0 0" xyz="-0.35 0 0"/>
      <geometry>
        <box size="0.1 0.64 1.0"/>
      </geometry>
      <material name="_red_material">
        <color rgba="1 0 0 1"/>
      </material>
      <!--xacro:material_red_block prefix="${name}"/-->
    </collision>
  </link>
  <joint name="window1_parent_frame_to_window1_left_link" type="fixed">
    <origin rpy="0 0 0" xyz="0 0 0"/>
    <parent link="window1_parent_frame"/>
    <child link="window1_left_link"/>
  </joint>
  <link name="window1_right_link">
    <visual>
      <origin rpy="0 0 0" xyz="0.35 0 0"/>
      <geometry>
        <box size="0.1 0.64 1.0"/>
      </geometry>
      <material name="_blue_material">
        <color rgba="0 0 1 1"/>
      </material>
      <!--xacro:material_blue_block prefix="${name}"/-->
    </visual>
    <collision>
      <origin rpy="0 0 0" xyz="0.35 0 0"/>
      <geometry>
        <box size="0.1 0.64 1.0"/>
      </geometry>
      <material name="_red_material">
        <color rgba="1 0 0 1"/>
      </material>
      <!--xacro:material_red_block prefix="${name}"/-->
    </collision>
  </link>
  <joint name="window1_parent_frame_to_window1_right_link" type="fixed">
    <origin rpy="0 0 0" xyz="0 0 0"/>
    <parent link="window1_parent_frame"/>
    <child link="window1_right_link"/>
  </joint>
  <!-- instantiating robots -->
  <link name="base_link">
    <visual>
      <origin rpy="0 0 0" xyz="0 0 0"/>
      <geometry>
        <mesh filename="package://abb_common/meshes/irb_2400/visual/base_link.STL"/>
      </geometry>
      <material name="abb_orange">
        <color rgba="1 0.43 0 1"/>
      </material>
    </visual>
    <collision>
      <geometry>
        <mesh filename="package://abb_common/meshes/irb_2400/collision/base_link.STL"/>
      </geometry>
      <material name="yellow">
        <color rgba="0 1 1 1"/>
      </material>
    </collision>
  </link>
  <link name="link_1">
    <visual>
      <origin rpy="0 0 0" xyz="0 0 0"/>
      <geometry>
        <mesh filename="package://abb_common/meshes/irb_2400/visual/link_1.STL"/>
      </geometry>
      <material name="abb_orange"/>
    </visual>
    <collision>
      <origin rpy="0 0 0" xyz="0 0 0"/>
      <geometry>
        <mesh filename="package://abb_common/meshes/irb_2400/collision/link_1.STL"/>
      </geometry>
      <material name="yellow"/>
    </collision>
  </link>
  <link name="link_2">
    <visual>
      <origin rpy="0 0 0" xyz="0 0 0"/>
      <geometry>
        <mesh filename="package://abb_common/meshes/irb_2400/visual/link_2.STL"/>
      </geometry>
      <material name="abb_orange"/>
    </visual>
    <collision>
      <origin rpy="0 0 0" xyz="0 0 0"/>
      <geometry>
        <mesh filename="package://abb_common/meshes/irb_2400/collision/link_2_whole.STL"/>
      </geometry>
      <material name="yellow"/>
    </collision>
  </link>
  <link name="link_3">
    <visual>
      <origin rpy="0 0 0" xyz="0 0 0"/>
      <geometry>
        <mesh filename="package://abb_common/meshes/irb_2400/visual/link_3.STL"/>
      </geometry>
      <material name="abb_orange"/>
    </visual>
    <collision>
      <origin rpy="0 0 0" xyz="0 0 0"/>
      <geometry>
        <mesh filename="package://abb_common/meshes/irb_2400/collision/link_3.STL"/>
      </geometry>
      <material name="yellow"/>
    </collision>
  </link>
  <link name="link_4">
    <visual>
      <origin rpy="0 0 0" xyz="0 0 0"/>
      <geometry>
        <mesh filename="package://abb_common/meshes/irb_2400/visual/link_4.STL"/>
      </geometry>
      <material name="abb_orange"/>
    </visual>
    <collision>
      <origin rpy="0 0 0" xyz="0 0 0"/>
      <geometry>
        <mesh filename="package://abb_common/meshes/irb_2400/collision/link_4.STL"/>
      </geometry>
      <material name="yellow"/>
    </collision>
  </link>
  <link name="link_5">
    <visual>
      <origin rpy="0 0 0" xyz="0 0 0"/>
      <geometry>
        <mesh filename="package://abb_common/meshes/irb_2400/visual/link_5.STL"/>
      </geometry>
      <material name="abb_orange"/>
    </visual>
    <collision>
      <origin rpy="0 0 0" xyz="0 0 0"/>
      <geometry>
        <mesh filename="package://abb_common/meshes/irb_2400/collision/link_5.STL"/>
      </geometry>
      <material name="yellow"/>
    </collision>
  </link>
  <link name="link_6">
    <visual>
      <origin rpy="0 0 0" xyz="0 0 0"/>
      <geometry>
        <mesh filename="package://abb_common/meshes/irb_2400/visual/link_6.STL"/>
      </geometry>
      <material name="abb_orange"/>
    </visual>
    <collision>
      <origin rpy="0 0 0" xyz="0 0 0"/>
      <geometry>
        <mesh filename="package://abb_common/meshes/irb_2400/collision/link_6.STL"/>
      </geometry>
      <material name="yellow"/>
    </collision>
  </link>
  <link name="tool0"/>
  <joint name="joint_1" type="revolute">
    <origin rpy="0 0 0" xyz="0 0 0"/>
    <parent link="base_link"/>
    <child link="link_1"/>
    <axis xyz="0 0 1"/>
    <limit effort="0" lower="-3.1416" upper="3.1416" velocity="2.618"/>
    <calibration falling="0" rising="0"/>
    <dynamics damping="0" friction="0"/>
  </joint>
  <joint name="joint_2" type="revolute">
    <origin rpy="0 0 0" xyz="0.1 0 0.615"/>
    <parent link="link_1"/>
    <child link="link_2"/>
    <axis xyz="0 1 0"/>
    <limit effort="0" lower="-1.7453" upper="1.9199" velocity="2.618"/>
    <calibration falling="0" rising="0"/>
    <dynamics damping="0" friction="0"/>
  </joint>
  <joint name="joint_3" type="revolute">
    <origin rpy="0 0 0" xyz="0 0 0.705"/>
    <parent link="link_2"/>
    <child link="link_3"/>
    <axis xyz="0 1 0"/>
    <limit effort="0" lower="-1.0472" upper="1.1345" velocity="2.618"/>
    <calibration falling="0" rising="0"/>
    <dynamics damping="0" friction="0"/>
  </joint>
  <joint name="joint_4" type="revolute">
    <origin rpy="0 0 0" xyz="0.258 0 0.135"/>
    <parent link="link_3"/>
    <child link="link_4"/>
    <axis xyz="1 0 0"/>
    <limit effort="0" lower="-3.49" upper="3.49" velocity="6.2832"/>
    <calibration falling="0" rising="0"/>
    <dynamics damping="0" friction="0"/>
  </joint>
  <joint name="joint_5" type="revolute">
    <origin rpy="0 0 0" xyz="0.497 0 0"/>
    <parent link="link_4"/>
    <child link="link_5"/>
    <axis xyz="0 1 0"/>
    <limit effort="0" lower="-2.0944" upper="2.0944" velocity="6.2832"/>
    <calibration falling="0" rising="0"/>
    <dynamics damping="0" friction="0"/>
  </joint>
  <joint name="joint_6" type="revolute">
    <origin rpy="0 0 0" xyz="0.085 0 0"/>
    <parent link="link_5"/>
    <child link="link_6"/>
    <axis xyz="1 0 0"/>
    <limit effort="0" lower="-6.9813" upper="6.9813" velocity="7.854"/>
    <calibration falling="0" rising="0"/>
    <dynamics damping="0" friction="0"/>
  </joint>
  <joint name="joint_6-tool0" type="fixed">
    <parent link="link_6"/>
    <child link="tool0"/>
    <origin rpy="0 0 0" xyz="0 0 0"/>
  </joint>
  <link name="gripper_palm">
    <visual>
      <geometry>
        <mesh filename="package://robotiq_s_model_visualization/meshes/s-model/visual/GRIPPER_OPEN_PALM.stl"/>
      </geometry>
      <material name="green">
        <color rgba="0 1 0 1"/>
      </material>
    </visual>
    <collision>
      <geometry>
        <mesh filename="package://robotiq_s_model_visualization/meshes/s-model/collision/GRIPPER_OPEN_PALM.stl"/>
      </geometry>
      <material name="yellow">
        <color rgba="0 1 1 1"/>
      </material>
    </collision>
  </link>
  <link name="gripper_finger_1">
    <visual>
      <geometry>
        <mesh filename="package://robotiq_s_model_visualization/meshes/s-model/visual/GRIPPER_OPEN_FINGER_1.stl"/>
      </geometry>
      <material name="green"/>
    </visual>
    <collision>
      <geometry>
        <mesh filename="package://robotiq_s_model_visualization/meshes/s-model/collision/GRIPPER_OPEN_FINGER_1.stl"/>
      </geometry>
      <material name="yellow"/>
    </collision>
  </link>
  <link name="gripper_finger_2">
    <visual>
      <geometry>
        <mesh filename="package://robotiq_s_model_visualization/meshes/s-model/visual/GRIPPER_OPEN_FINGER_2.stl"/>
      </geometry>
      <material name="green"/>
    </visual>
    <collision>
      <geometry>
        <mesh filename="package://robotiq_s_model_visualization/meshes/s-model/collision/GRIPPER_OPEN_FINGER_2.stl"/>
      </geometry>
      <material name="yellow"/>
    </collision>
  </link>
  <link name="gripper_finger_3">
    <visual>
      <geometry>
        <mesh filename="package://robotiq_s_model_visualization/meshes/s-model/visual/GRIPPER_OPEN_FINGER_3.stl"/>
      </geometry>
      <material name="green"/>
    </visual>
    <collision>
      <geometry>
        <mesh filename="package://robotiq_s_model_visualization/meshes/s-model/collision/GRIPPER_OPEN_FINGER_3.stl"/>
      </geometry>
      <material name="yellow"/>
    </collision>
  </link>
  <joint name="gripper_joint_1" type="fixed">
    <parent link="gripper_palm"/>
    <child link="gripper_finger_1"/>
    <origin rpy="0 0 0" xyz="0 0 0"/>
  </joint>
  <joint name="gripper_joint_2" type="fixed">
    <parent link="gripper_palm"/>
    <child link="gripper_finger_2"/>
    <origin rpy="0 0 0" xyz="0 0 0"/>
  </joint>
  <joint name="gripper_joint_3" type="fixed">
    <parent link="gripper_palm"/>
    <child link="gripper_finger_3"/>
    <origin rpy="0 0 0" xyz="0 0 0"/>
  </joint>
  <link name="window2_parent_frame"/>
  <link name="window2_top_link">
    <visual>
      <origin rpy="0 0 0" xyz="0 0.37 0"/>
      <geometry>
        <box size="0.8 0.1 1.0"/>
      </geometry>
      <material name="_yellow_material">
        <color rgba="1 1 0 1"/>
      </material>
      <!--xacro:material_blue_block prefix="${name}"/-->
    </visual>
    <collision>
      <origin rpy="0 0 0" xyz="0 0.37 0"/>
      <geometry>
        <box size="0.8 0.1 1.0"/>
      </geometry>
      <material name="_red_material">
        <color rgba="1 0 0 1"/>
      </material>
      <!--xacro:material_red_block prefix="${name}"/-->
    </collision>
  </link>
  <joint name="window2_parent_frame_to_window2_top_link" type="fixed">
    <origin rpy="0 0 0" xyz="0 0 0"/>
    <parent link="window2_parent_frame"/>
    <child link="window2_top_link"/>
  </joint>
  <link name="window2_bottom_link">
    <visual>
      <origin rpy="0 0 0" xyz="0 -0.37 0"/>
      <geometry>
        <box size="0.8 0.1 1.0"/>
      </geometry>
      <material name="_yellow_material">
        <color rgba="1 1 0 1"/>
      </material>
      <!--xacro:material_blue_block prefix="${name}"/-->
    </visual>
    <collision>
      <origin rpy="0 0 0" xyz="0 -0.37 0"/>
      <geometry>
        <box size="0.8 0.1 1.0"/>
      </geometry>
      <material name="_red_material">
        <color rgba="1 0 0 1"/>
      </material>
      <!--xacro:material_red_block prefix="${name}"/-->
    </collision>
  </link>
  <joint name="window2_parent_frame_to_window2_bottom_link" type="fixed">
    <origin rpy="0 0 0" xyz="0 0 0"/>
    <parent link="window2_parent_frame"/>
    <child link="window2_bottom_link"/>
  </joint>
  <link name="window2_left_link">
    <visual>
      <origin rpy="0 0 0" xyz="-0.35 0 0"/>
      <geometry>
        <box size="0.1 0.64 1.0"/>
      </geometry>
      <material name="_yellow_material">
        <color rgba="1 1 0 1"/>
      </material>
      <!--xacro:material_blue_block prefix="${name}"/-->
    </visual>
    <collision>
      <origin rpy="0 0 0" xyz="-0.35 0 0"/>
      <geometry>
        <box size="0.1 0.64 1.0"/>
      </geometry>
      <material name="_red_material">
        <color rgba="1 0 0 1"/>
      </material>
      <!--xacro:material_red_block prefix="${name}"/-->
    </collision>
  </link>
  <joint name="window2_parent_frame_to_window2_left_link" type="fixed">
    <origin rpy="0 0 0" xyz="0 0 0"/>
    <parent link="window2_parent_frame"/>
    <child link="window2_left_link"/>
  </joint>
  <link name="window2_right_link">
    <visual>
      <origin rpy="0 0 0" xyz="0.35 0 0"/>
      <geometry>
        <box size="0.1 0.64 1.0"/>
      </geometry>
      <material name="_yellow_material">
        <color rgba="1 1 0 1"/>
      </material>
      <!--xacro:material_blue_block prefix="${name}"/-->
    </visual>
    <collision>
      <origin rpy="0 0 0" xyz="0.35 0 0"/>
      <geometry>
        <box size="0.1 0.64 1.0"/>
      </geometry>
      <material name="_red_material">
        <color rgba="1 0 0 1"/>
      </material>
      <!--xacro:material_red_block prefix="${name}"/-->
    </collision>
  </link>
  <joint name="window2_parent_frame_to_window2_right_link" type="fixed">
    <origin rpy="0 0 0" xyz="0 0 0"/>
    <parent link="window2_parent_frame"/>
    <child link="window2_right_link"/>
  </joint>
  <!-- link definitions -->
  <link name="world_frame"/>
  <!-- joint  definitions -->
  <joint name="world_to_window1" type="fixed">
    <origin rpy="0 1.57 0" xyz="2.0 0 0.4"/>
    <parent link="world_frame"/>
    <child link="window1_parent_frame"/>
  </joint>
  <joint name="world_to_window2" type="fixed">
    <origin rpy="0 1.57 0" xyz="2.0 0 1.2"/>
    <parent link="world_frame"/>
    <child link="window2_parent_frame"/>
  </joint>
  <joint name="world_to_robot_base" type="fixed">
    <origin rpy="0 0 0" xyz="0 0 0"/>
    <parent link="world_frame"/>
    <child link="base_link"/>
  </joint>
  <joint name="wrist_to_gripper" type="fixed">
    <origin rpy="0 1.57 0" xyz="0.16 0 0"/>
    <parent link="tool0"/>
    <child link="gripper_palm"/>
  </joint>
</robot>

