<?xml version="1.0" ?>
<!-- =================================================================================== -->
<!-- |    This document was autogenerated by xacro from sia20d_navigation_environment.xacro | -->
<!-- |    EDITING THIS FILE BY HAND IS NOT RECOMMENDED                                 | -->
<!-- =================================================================================== -->
<robot name="sia20d_navigation_environment" xmlns:xacro="http://ros.org/wiki/xacro">
  <description>
		Creates a window of specified dimensions using boxes
	</description>
  <description>
		Contains a series of material blocks with predefined colors that can be used
		in any visual element of a urdf model.
	</description>
  <description>
		Contains a series of material blocks with predefined colors that can be used
		in any visual element of a urdf model.
	</description>
  <!-- parameters -->
  <!-- instantiating windows -->
  <link name="window1_parent_frame"/>
  <link name="window1_top_link">
    <visual>
      <origin rpy="0 0 0" xyz="0 0.37 0"/>
      <geometry>
        <box size="0.52 0.1 1.0"/>
      </geometry>
      <material name="_blue_material">
        <color rgba="0 0 1 1"/>
      </material>
      <!--xacro:material_blue_block prefix="${name}"/-->
    </visual>
    <collision>
      <origin rpy="0 0 0" xyz="0 0.37 0"/>
      <geometry>
        <box size="0.52 0.1 1.0"/>
      </geometry>
      <material name="_red_material">
        <color rgba="1 0 0 1"/>
      </material>
      <!--xacro:material_red_block prefix="${name}"/-->
    </collision>
  </link>
  <joint name="window1_parent_frame_to_window1_top_link" type="fixed">
    <origin rpy="0 0 0" xyz="0 0 0"/>
    <parent link="window1_parent_frame"/>
    <child link="window1_top_link"/>
  </joint>
  <link name="window1_bottom_link">
    <visual>
      <origin rpy="0 0 0" xyz="0 -0.37 0"/>
      <geometry>
        <box size="0.52 0.1 1.0"/>
      </geometry>
      <material name="_blue_material">
        <color rgba="0 0 1 1"/>
      </material>
      <!--xacro:material_blue_block prefix="${name}"/-->
    </visual>
    <collision>
      <origin rpy="0 0 0" xyz="0 -0.37 0"/>
      <geometry>
        <box size="0.52 0.1 1.0"/>
      </geometry>
      <material name="_red_material">
        <color rgba="1 0 0 1"/>
      </material>
      <!--xacro:material_red_block prefix="${name}"/-->
    </collision>
  </link>
  <joint name="window1_parent_frame_to_window1_bottom_link" type="fixed">
    <origin rpy="0 0 0" xyz="0 0 0"/>
    <parent link="window1_parent_frame"/>
    <child link="window1_bottom_link"/>
  </joint>
  <link name="window1_left_link">
    <visual>
      <origin rpy="0 0 0" xyz="-0.21 0 0"/>
      <geometry>
        <box size="0.1 0.64 1.0"/>
      </geometry>
      <material name="_blue_material">
        <color rgba="0 0 1 1"/>
      </material>
      <!--xacro:material_blue_block prefix="${name}"/-->
    </visual>
    <collision>
      <origin rpy="0 0 0" xyz="-0.21 0 0"/>
      <geometry>
        <box size="0.1 0.64 1.0"/>
      </geometry>
      <material name="_red_material">
        <color rgba="1 0 0 1"/>
      </material>
      <!--xacro:material_red_block prefix="${name}"/-->
    </collision>
  </link>
  <joint name="window1_parent_frame_to_window1_left_link" type="fixed">
    <origin rpy="0 0 0" xyz="0 0 0"/>
    <parent link="window1_parent_frame"/>
    <child link="window1_left_link"/>
  </joint>
  <link name="window1_right_link">
    <visual>
      <origin rpy="0 0 0" xyz="0.21 0 0"/>
      <geometry>
        <box size="0.1 0.64 1.0"/>
      </geometry>
      <material name="_blue_material">
        <color rgba="0 0 1 1"/>
      </material>
      <!--xacro:material_blue_block prefix="${name}"/-->
    </visual>
    <collision>
      <origin rpy="0 0 0" xyz="0.21 0 0"/>
      <geometry>
        <box size="0.1 0.64 1.0"/>
      </geometry>
      <material name="_red_material">
        <color rgba="1 0 0 1"/>
      </material>
      <!--xacro:material_red_block prefix="${name}"/-->
    </collision>
  </link>
  <joint name="window1_parent_frame_to_window1_right_link" type="fixed">
    <origin rpy="0 0 0" xyz="0 0 0"/>
    <parent link="window1_parent_frame"/>
    <child link="window1_right_link"/>
  </joint>
  <!-- instantiating robots -->
  <link name="base_link">
    <visual>
      <geometry>
        <mesh filename="package://motoman_config/meshes/sia20d/visual/MOTOMAN_BASE.stl"/>
      </geometry>
      <material name="blue">
        <color rgba="0 0 1 1"/>
      </material>
    </visual>
    <collision>
      <geometry>
        <mesh filename="package://motoman_config/meshes/sia20d/collision/MOTOMAN_BASE.stl"/>
      </geometry>
      <material name="yellow">
        <color rgba="0 1 1 1"/>
      </material>
    </collision>
  </link>
  <link name="link_s">
    <visual>
      <origin rpy="0 0 3.1416" xyz="0 0 0"/>
      <geometry>
        <mesh filename="package://motoman_config/meshes/sia20d/visual/MOTOMAN_AXIS_S.stl"/>
      </geometry>
      <material name="silver">
        <color rgba="0.8 0.8 0.8 1"/>
      </material>
    </visual>
    <collision>
      <origin rpy="0 0 3.1416" xyz="0 0 0"/>
      <geometry>
        <mesh filename="package://motoman_config/meshes/sia20d/collision/MOTOMAN_AXIS_S.stl"/>
      </geometry>
      <material name="yellow"/>
    </collision>
  </link>
  <link name="link_l">
    <visual>
      <origin rpy="1.57 3.1416 3.1416" xyz="0 0 0"/>
      <geometry>
        <mesh filename="package://motoman_config/meshes/sia20d/visual/MOTOMAN_AXIS_L.stl"/>
      </geometry>
      <material name="blue"/>
    </visual>
    <collision>
      <origin rpy="1.57 3.1416 3.1416" xyz="0 0 0"/>
      <geometry>
        <mesh filename="package://motoman_config/meshes/sia20d/collision/MOTOMAN_AXIS_L.stl"/>
      </geometry>
      <material name="yellow"/>
    </collision>
  </link>
  <link name="link_e">
    <visual>
      <origin rpy="0 0 0" xyz="0 0 0"/>
      <geometry>
        <mesh filename="package://motoman_config/meshes/sia20d/visual/MOTOMAN_AXIS_E.stl"/>
      </geometry>
      <material name="silver"/>
    </visual>
    <collision>
      <origin rpy="0 0 0" xyz="0 0 0"/>
      <geometry>
        <mesh filename="package://motoman_config/meshes/sia20d/collision/MOTOMAN_AXIS_E.stl"/>
      </geometry>
      <material name="yellow"/>
    </collision>
  </link>
  <link name="link_u">
    <visual>
      <origin rpy="1.57 -3.1415 3.1416" xyz="0 0 0"/>
      <geometry>
        <mesh filename="package://motoman_config/meshes/sia20d/visual/MOTOMAN_AXIS_U.stl"/>
      </geometry>
      <material name="blue"/>
    </visual>
    <collision>
      <origin rpy="1.57 -3.1415 3.1416" xyz="0 0 0"/>
      <geometry>
        <mesh filename="package://motoman_config/meshes/sia20d/collision/MOTOMAN_AXIS_U.stl"/>
      </geometry>
      <material name="yellow"/>
    </collision>
  </link>
  <link name="link_r">
    <visual>
      <origin rpy="0 0 0" xyz="0 0 0"/>
      <geometry>
        <mesh filename="package://motoman_config/meshes/sia20d/visual/MOTOMAN_AXIS_R.stl"/>
      </geometry>
      <material name="silver"/>
    </visual>
    <collision>
      <origin rpy="0 0 0" xyz="0 0 0"/>
      <geometry>
        <mesh filename="package://motoman_config/meshes/sia20d/collision/MOTOMAN_AXIS_R.stl"/>
      </geometry>
      <material name="yellow"/>
    </collision>
  </link>
  <link name="link_b">
    <visual>
      <origin rpy="-1.57 0 0" xyz="0 0 0"/>
      <geometry>
        <mesh filename="package://motoman_config/meshes/sia20d/visual/MOTOMAN_AXIS_B.stl"/>
      </geometry>
      <material name="blue"/>
    </visual>
    <collision>
      <origin rpy="-1.57 0 0" xyz="0 0 0"/>
      <geometry>
        <mesh filename="package://motoman_config/meshes/sia20d/collision/MOTOMAN_AXIS_B.stl"/>
      </geometry>
      <material name="yellow"/>
    </collision>
  </link>
  <link name="link_t">
    <visual>
      <geometry>
        <mesh filename="package://motoman_config/meshes/sia20d/visual/MOTOMAN_AXIS_T.stl"/>
      </geometry>
      <material name="silver"/>
    </visual>
    <collision>
      <geometry>
        <mesh filename="package://motoman_config/meshes/sia20d/collision/MOTOMAN_AXIS_T.stl"/>
      </geometry>
      <material name="yellow"/>
    </collision>
  </link>
  <link name="tool0"/>
  <joint name="joint_s" type="revolute">
    <parent link="base_link"/>
    <child link="link_s"/>
    <origin rpy="0 0 0" xyz="0 0 0.41"/>
    <axis xyz="0 0 1"/>
    <limit effort="100" lower="-3.1416" upper="3.1416" velocity="2.26"/>
  </joint>
  <joint name="joint_l" type="revolute">
    <parent link="link_s"/>
    <child link="link_l"/>
    <origin rpy="0 0 0" xyz="0 0 0"/>
    <axis xyz="0 1 0"/>
    <limit effort="100" lower="-1.91" upper="1.91" velocity="2.26"/>
  </joint>
  <joint name="joint_e" type="revolute">
    <parent link="link_l"/>
    <child link="link_e"/>
    <origin rpy="0 0 0" xyz="0 0 0.49"/>
    <axis xyz="0 0 1"/>
    <limit effort="100" lower="-2.96" upper="2.96" velocity="2.96"/>
  </joint>
  <joint name="joint_u" type="revolute">
    <parent link="link_e"/>
    <child link="link_u"/>
    <origin rpy="0 0 0" xyz="0 0 0"/>
    <axis xyz="0 -1 0"/>
    <limit effort="100" lower="-2.26" upper="2.26" velocity="2.96"/>
  </joint>
  <joint name="joint_r" type="revolute">
    <parent link="link_u"/>
    <child link="link_r"/>
    <origin rpy="0 0 0" xyz="0 0 0.420"/>
    <axis xyz="0 0 -1"/>
    <limit effort="100" lower="-3.1416" upper="3.1416" velocity="3.48"/>
  </joint>
  <joint name="joint_b" type="revolute">
    <parent link="link_r"/>
    <child link="link_b"/>
    <origin rpy="0 0 0" xyz="0 0 0"/>
    <axis xyz="0 -1 0"/>
    <limit effort="100" lower="-1.91" upper="1.91" velocity="3.48"/>
  </joint>
  <joint name="joint_t" type="revolute">
    <parent link="link_b"/>
    <child link="link_t"/>
    <origin rpy="0 0 0" xyz="0 0 0.18"/>
    <axis xyz="0 0 -1"/>
    <limit effort="100" lower="-3.1416" upper="3.1416" velocity="6.97"/>
  </joint>
  <joint name="link_t-tool0" type="fixed">
    <origin rpy="0 -1.571 0" xyz="0 0 0.0"/>
    <parent link="link_t"/>
    <child link="tool0"/>
  </joint>
  <link name="palm">
    <visual>
      <geometry>
        <mesh filename="package://robotiq_s_model_visualization/meshes/s-model/visual/GRIPPER_OPEN_PALM.stl"/>
      </geometry>
      <material name="green">
        <color rgba="0 1 0 1"/>
      </material>
    </visual>
    <collision>
      <geometry>
        <mesh filename="package://robotiq_s_model_visualization/meshes/s-model/collision/GRIPPER_OPEN_PALM.stl"/>
      </geometry>
      <material name="yellow">
        <color rgba="0 1 1 1"/>
      </material>
    </collision>
  </link>
  <link name="finger_1">
    <visual>
      <geometry>
        <mesh filename="package://robotiq_s_model_visualization/meshes/s-model/visual/GRIPPER_OPEN_FINGER_1.stl"/>
      </geometry>
      <material name="green"/>
    </visual>
    <collision>
      <geometry>
        <mesh filename="package://robotiq_s_model_visualization/meshes/s-model/collision/GRIPPER_OPEN_FINGER_1.stl"/>
      </geometry>
      <material name="yellow"/>
    </collision>
  </link>
  <link name="finger_2">
    <visual>
      <geometry>
        <mesh filename="package://robotiq_s_model_visualization/meshes/s-model/visual/GRIPPER_OPEN_FINGER_2.stl"/>
      </geometry>
      <material name="green"/>
    </visual>
    <collision>
      <geometry>
        <mesh filename="package://robotiq_s_model_visualization/meshes/s-model/collision/GRIPPER_OPEN_FINGER_2.stl"/>
      </geometry>
      <material name="yellow"/>
    </collision>
  </link>
  <link name="finger_3">
    <visual>
      <geometry>
        <mesh filename="package://robotiq_s_model_visualization/meshes/s-model/visual/GRIPPER_OPEN_FINGER_3.stl"/>
      </geometry>
      <material name="green"/>
    </visual>
    <collision>
      <geometry>
        <mesh filename="package://robotiq_s_model_visualization/meshes/s-model/collision/GRIPPER_OPEN_FINGER_3.stl"/>
      </geometry>
      <material name="yellow"/>
    </collision>
  </link>
  <joint name="joint_1" type="fixed">
    <parent link="palm"/>
    <child link="finger_1"/>
    <origin rpy="0 0 0" xyz="0 0 0"/>
  </joint>
  <joint name="joint_2" type="fixed">
    <parent link="palm"/>
    <child link="finger_2"/>
    <origin rpy="0 0 0" xyz="0 0 0"/>
  </joint>
  <joint name="joint_3" type="fixed">
    <parent link="palm"/>
    <child link="finger_3"/>
    <origin rpy="0 0 0" xyz="0 0 0"/>
  </joint>
  <link name="window2_parent_frame"/>
  <link name="window2_top_link">
    <visual>
      <origin rpy="0 0 0" xyz="0 0.37 0"/>
      <geometry>
        <box size="0.52 0.1 1.0"/>
      </geometry>
      <material name="_yellow_material">
        <color rgba="1 1 0 1"/>
      </material>
      <!--xacro:material_blue_block prefix="${name}"/-->
    </visual>
    <collision>
      <origin rpy="0 0 0" xyz="0 0.37 0"/>
      <geometry>
        <box size="0.52 0.1 1.0"/>
      </geometry>
      <material name="_red_material">
        <color rgba="1 0 0 1"/>
      </material>
      <!--xacro:material_red_block prefix="${name}"/-->
    </collision>
  </link>
  <joint name="window2_parent_frame_to_window2_top_link" type="fixed">
    <origin rpy="0 0 0" xyz="0 0 0"/>
    <parent link="window2_parent_frame"/>
    <child link="window2_top_link"/>
  </joint>
  <link name="window2_bottom_link">
    <visual>
      <origin rpy="0 0 0" xyz="0 -0.37 0"/>
      <geometry>
        <box size="0.52 0.1 1.0"/>
      </geometry>
      <material name="_yellow_material">
        <color rgba="1 1 0 1"/>
      </material>
      <!--xacro:material_blue_block prefix="${name}"/-->
    </visual>
    <collision>
      <origin rpy="0 0 0" xyz="0 -0.37 0"/>
      <geometry>
        <box size="0.52 0.1 1.0"/>
      </geometry>
      <material name="_red_material">
        <color rgba="1 0 0 1"/>
      </material>
      <!--xacro:material_red_block prefix="${name}"/-->
    </collision>
  </link>
  <joint name="window2_parent_frame_to_window2_bottom_link" type="fixed">
    <origin rpy="0 0 0" xyz="0 0 0"/>
    <parent link="window2_parent_frame"/>
    <child link="window2_bottom_link"/>
  </joint>
  <link name="window2_left_link">
    <visual>
      <origin rpy="0 0 0" xyz="-0.21 0 0"/>
      <geometry>
        <box size="0.1 0.64 1.0"/>
      </geometry>
      <material name="_yellow_material">
        <color rgba="1 1 0 1"/>
      </material>
      <!--xacro:material_blue_block prefix="${name}"/-->
    </visual>
    <collision>
      <origin rpy="0 0 0" xyz="-0.21 0 0"/>
      <geometry>
        <box size="0.1 0.64 1.0"/>
      </geometry>
      <material name="_red_material">
        <color rgba="1 0 0 1"/>
      </material>
      <!--xacro:material_red_block prefix="${name}"/-->
    </collision>
  </link>
  <joint name="window2_parent_frame_to_window2_left_link" type="fixed">
    <origin rpy="0 0 0" xyz="0 0 0"/>
    <parent link="window2_parent_frame"/>
    <child link="window2_left_link"/>
  </joint>
  <link name="window2_right_link">
    <visual>
      <origin rpy="0 0 0" xyz="0.21 0 0"/>
      <geometry>
        <box size="0.1 0.64 1.0"/>
      </geometry>
      <material name="_yellow_material">
        <color rgba="1 1 0 1"/>
      </material>
      <!--xacro:material_blue_block prefix="${name}"/-->
    </visual>
    <collision>
      <origin rpy="0 0 0" xyz="0.21 0 0"/>
      <geometry>
        <box size="0.1 0.64 1.0"/>
      </geometry>
      <material name="_red_material">
        <color rgba="1 0 0 1"/>
      </material>
      <!--xacro:material_red_block prefix="${name}"/-->
    </collision>
  </link>
  <joint name="window2_parent_frame_to_window2_right_link" type="fixed">
    <origin rpy="0 0 0" xyz="0 0 0"/>
    <parent link="window2_parent_frame"/>
    <child link="window2_right_link"/>
  </joint>
  <!-- link definitions -->
  <link name="world_frame"/>
  <!-- joint  definitions -->
  <joint name="world_to_window1" type="fixed">
    <origin rpy="0 1.57 0" xyz="1.0 0 0.26"/>
    <parent link="world_frame"/>
    <child link="window1_parent_frame"/>
  </joint>
  <joint name="world_to_window2" type="fixed">
    <origin rpy="0 1.57 0" xyz="1.0 0 0.78"/>
    <parent link="world_frame"/>
    <child link="window2_parent_frame"/>
  </joint>
  <joint name="world_to_robot_base" type="fixed">
    <origin rpy="0 0 0" xyz="0 0 0"/>
    <parent link="world_frame"/>
    <child link="base_link"/>
  </joint>
  <joint name="wrist_to_gripper" type="fixed">
    <origin rpy="0 0 0" xyz="0 0 0.16"/>
    <parent link="link_t"/>
    <child link="palm"/>
  </joint>
</robot>

